<?xml version="1.0" ?>
<!-- =================================================================================== -->
<!-- |    This document was autogenerated by xacro from /home/alexoberco/ras_ws/src/junior2/robot_arm/urdf/robot_arm_complete.urdf.xacro | -->
<!-- |    EDITING THIS FILE BY HAND IS NOT RECOMMENDED                                 | -->
<!-- =================================================================================== -->
<robot name="robot_arm">
    <!-- Links -->
    <link name="world" />
    <link name="base_link">
        <visual>
            <origin rpy="0 0 0" xyz="-0.5 -0.5 0" />
            <geometry>
                <mesh filename="package://robot_arm/mesh/basement_robot.STL" scale="0.01 0.01 0.01" />
            </geometry>
        </visual>
        <collision>
            <origin rpy="0 0 0" xyz="-0.5 -0.5 0" />
            <geometry>
                <mesh filename="package://robot_arm/mesh/basement_robot.STL" scale="0.01 0.01 0.01" />
            </geometry>
        </collision>
        <inertial>
            <mass value="0.1" />
            <origin xyz="0 0 0" rpy="0 0 0" />
            <inertia ixx="0.03" iyy="0.03" izz="0.03" ixy="0.0" ixz="0.0" iyz="0.0" />
        </inertial>
    </link>
    <link name="base_plate">
        <visual>
            <origin rpy="0 0 0" xyz="-0.39 -0.39 -0.56" />
            <geometry>
                <mesh filename="package://robot_arm/mesh/base_plate.STL" scale="0.01 0.01 0.01" />
            </geometry>
        </visual>
        <collision>
            <origin rpy="0 0 0" xyz="-0.39 -0.39 -0.56" />
            <geometry>
                <mesh filename="package://robot_arm/mesh/base_plate.STL" scale="0.01 0.01 0.01" />
            </geometry>
        </collision>
        <inertial>
            <mass value="0.1" />
            <origin xyz="0 0 0" rpy="0 0 0" />
            <inertia ixx="0.03" iyy="0.03" izz="0.03" ixy="0.0" ixz="0.0" iyz="0.0" />
        </inertial>
    </link>
    <link name="forward_drive_arm">
        <visual>
            <origin rpy=" 0 -1.570796326795 1.570796326795" xyz="0.19 0.06 -0.08" />
            <geometry>
                <mesh filename="package://robot_arm/mesh/forward_drive_arm.STL" scale="0.01 0.01 0.01" />
            </geometry>
        </visual>
        <collision>
            <origin rpy=" 0 -1.570796326795 1.570796326795" xyz="0.19 0.06 -0.08" />
            <geometry>
                <mesh filename="package://robot_arm/mesh/forward_drive_arm.STL" scale="0.01 0.01 0.01" />
            </geometry>
        </collision>
        <inertial>
            <mass value="0.1" />
            <origin xyz="0 0 0" rpy="0 0 0" />
            <inertia ixx="0.03" iyy="0.03" izz="0.03" ixy="0.0" ixz="0.0" iyz="0.0" />
        </inertial>
    </link>
    <link name="horizontal_arm">
        <visual>
            <origin rpy="1.570796326795 0 1.570796326795" xyz="-0.03 -0.4 -0.06" />
            <geometry>
                <mesh filename="package://robot_arm/mesh/horizontal_arm.STL" scale="0.01 0.01 0.01" />
            </geometry>
        </visual>
        <collision>
            <origin rpy="1.570796326795 0 1.570796326795" xyz="-0.03 -0.4 -0.06" />
            <geometry>
                <mesh filename="package://robot_arm/mesh/horizontal_arm.STL" scale="0.01 0.01 0.01" />
            </geometry>
        </collision>
        <inertial>
            <mass value="0.1" />
            <origin xyz="0 0 0" rpy="0 0 0" />
            <inertia ixx="0.03" iyy="0.03" izz="0.03" ixy="0.0" ixz="0.0" iyz="0.0" />
        </inertial>
    </link>
    <link name="claw_support">
        <visual>
            <origin rpy="0 0 1.570796326795" xyz="0 -0.05 -0.15" />
            <geometry>
                <mesh filename="package://robot_arm/mesh/claw_support.STL" scale="0.01 0.01 0.01" />
            </geometry>
        </visual>
        <collision>
            <origin rpy="0 0 1.570796326795" xyz="0 -0.05 -0.15" />
            <geometry>
                <mesh filename="package://robot_arm/mesh/claw_support.STL" scale="0.01 0.01 0.01" />
            </geometry>
        </collision>
        <inertial>
            <mass value="0.1" />
            <origin xyz="0 0 0" rpy="0 0 0" />
            <inertia ixx="0.03" iyy="0.03" izz="0.03" ixy="0.0" ixz="0.0" iyz="0.0" />
        </inertial>
    </link>
    <link name="gripper_right">
        <visual>
            <origin rpy="0 0 -1.570796326795" xyz="-0.1 0.50 -0.1" />
            <geometry>
                <mesh filename="package://robot_arm/mesh/right_finger.STL" scale="0.01 0.01 0.01" />
            </geometry>
        </visual>
        <collision>
            <origin rpy="0 0 -1.570796326795" xyz="-0.1 0.50 -0.1" />
            <geometry>
                <mesh filename="package://robot_arm/mesh/right_finger.STL" scale="0.01 0.01 0.01" />
            </geometry>
        </collision>
        <inertial>
            <mass value="0.1" />
            <origin xyz="0 0 0" rpy="0 0 0" />
            <inertia ixx="0.03" iyy="0.03" izz="0.03" ixy="0.0" ixz="0.0" iyz="0.0" />
        </inertial>
    </link>
    <link name="gripper_left">
        <visual>
            <origin rpy="0 0 -1.570796326795" xyz="-0.04 0.50 -0.1" />
            <geometry>
                <mesh filename="package://robot_arm/mesh/left_finger.STL" scale="0.01 0.01 0.01" />
            </geometry>
        </visual>
        <collision>
            <origin rpy="0 0 -1.570796326795" xyz="-0.04 0.50 -0.1" />
            <geometry>
                <mesh filename="package://robot_arm/mesh/left_finger.STL" scale="0.01 0.01 0.01" />
            </geometry>
        </collision>
        <inertial>
            <mass value="0.1" />
            <origin xyz="0 0 0" rpy="0 0 0" />
            <inertia ixx="0.03" iyy="0.03" izz="0.03" ixy="0.0" ixz="0.0" iyz="0.0" />
        </inertial>
    </link>
    <link name="tool_link" />
    <!-- Joints -->
    <joint name="virtual_joint" type="fixed">
        <parent link="world" />
        <child link="base_link" />
        <origin rpy="0 0 0" xyz="0 0 0" />
    </joint>
    <joint name="joint_1" type="revolute">
        <parent link="base_link" />
        <child link="base_plate" />
        <origin xyz="0 0 0.307" />
        <axis xyz="0 0 1" />
        <limit effort="30" lower="-1.570796326795" upper="1.570796326795" velocity="10" />
    </joint>
    <joint name="joint_2" type="revolute">
        <parent link="base_plate" />
        <child link="forward_drive_arm" />
        <origin xyz="-0.02 0 0.35" />
        <axis xyz="1 0 0" />
        <limit effort="30" lower="-1.570796326795" upper="1.570796326795" velocity="10" />
    </joint>
    <joint name="joint_3" type="revolute">
        <parent link="forward_drive_arm" />
        <child link="horizontal_arm" />
        <origin xyz="0 0 0.8" />
        <axis xyz="1 0 0" />
        <limit effort="30" lower="-1.570796326795" upper="1.570796326795" velocity="10" />
    </joint>
    <joint name="horizontal_arm_to_claw_support" type="fixed">
        <parent link="horizontal_arm" />
        <child link="claw_support" />
        <origin xyz="0 0.82 0" />
    </joint>
    <joint name="joint_4" type="revolute">
        <parent link="claw_support" />
        <child link="gripper_right" />
        <origin xyz="-0.04 0.13 -0.1" />
        <axis xyz="0 0 1" />
        <limit effort="30" lower="-1.570796326795" upper="0" velocity="10" />
    </joint>
    <joint name="joint_5" type="revolute">
        <parent link="claw_support" />
        <child link="gripper_left" />
        <origin xyz="-0.22 0.13 -0.1" />
        <axis xyz="0 0 1" />
        <limit effort="30" lower="0" upper="1.570796326795" velocity="10" />
        <mimic joint="joint_4" multiplier="-1" offset="0" />
    </joint>
    <joint name="gripper_right_to_tool" type="fixed">
        <parent link="gripper_right" />
        <child link="tool_link" />
        <origin xyz="0 0 0" />
    </joint>
    <transmission name="trans_joint_1">
        <type>transmission_interface/SimpleTransmission</type>
        <joint name="joint_1">
            <hardwareInterface>hardware_interface/PositionJointInterface</hardwareInterface>
        </joint>
        <actuator name="joint_1_motor">
            <hardwareInterface>hardware_interface/PositionJointInterface</hardwareInterface>
            <mechanicalReduction>1</mechanicalReduction>
        </actuator>
    </transmission>
    <transmission name="trans_joint_2">
        <type>transmission_interface/SimpleTransmission</type>
        <joint name="joint_2">
            <hardwareInterface>hardware_interface/PositionJointInterface</hardwareInterface>
        </joint>
        <actuator name="joint_2_motor">
            <hardwareInterface>hardware_interface/PositionJointInterface</hardwareInterface>
            <mechanicalReduction>1</mechanicalReduction>
        </actuator>
    </transmission>
    <transmission name="trans_joint_3">
        <type>transmission_interface/SimpleTransmission</type>
        <joint name="joint_3">
            <hardwareInterface>hardware_interface/PositionJointInterface</hardwareInterface>
        </joint>
        <actuator name="joint_3_motor">
            <hardwareInterface>hardware_interface/PositionJointInterface</hardwareInterface>
            <mechanicalReduction>1</mechanicalReduction>
        </actuator>
    </transmission>
    <transmission name="trans_joint_4">
        <type>transmission_interface/SimpleTransmission</type>
        <joint name="joint_4">
            <hardwareInterface>hardware_interface/EffortJointInterface</hardwareInterface>
        </joint>
        <actuator name="joint_4_motor">
            <hardwareInterface>hardware_interface/EffortJointInterface</hardwareInterface>
            <mechanicalReduction>1</mechanicalReduction>
        </actuator>
    </transmission>
    <transmission name="trans_joint_5">
        <type>transmission_interface/SimpleTransmission</type>
        <joint name="joint_5">
            <hardwareInterface>hardware_interface/EffortJointInterface</hardwareInterface>
        </joint>
        <actuator name="joint_5_motor">
            <hardwareInterface>hardware_interface/EffortJointInterface</hardwareInterface>
            <mechanicalReduction>1</mechanicalReduction>
        </actuator>
    </transmission>
    <gazebo>
        <plugin name="gazebo_ros_control">
            <robotNamespace>/</robotNamespace>
        </plugin>
    </gazebo>
</robot>

